Traceback (most recent call last):
  File "/usr/local/py-utils/bin/pytest", line 8, in <module>
    sys.exit(console_main())
  File "/usr/local/py-utils/venvs/pytest/lib/python3.10/site-packages/_pytest/config/__init__.py", line 189, in console_main
    code = main()
  File "/usr/local/py-utils/venvs/pytest/lib/python3.10/site-packages/_pytest/config/__init__.py", line 147, in main
    config = _prepareconfig(args, plugins)
  File "/usr/local/py-utils/venvs/pytest/lib/python3.10/site-packages/_pytest/config/__init__.py", line 328, in _prepareconfig
    config = pluginmanager.hook.pytest_cmdline_parse(
  File "/usr/local/py-utils/venvs/pytest/lib/python3.10/site-packages/pluggy/_hooks.py", line 433, in __call__
    return self._hookexec(self.name, self._hookimpls, kwargs, firstresult)
  File "/usr/local/py-utils/venvs/pytest/lib/python3.10/site-packages/pluggy/_manager.py", line 112, in _hookexec
    return self._inner_hookexec(hook_name, methods, kwargs, firstresult)
  File "/usr/local/py-utils/venvs/pytest/lib/python3.10/site-packages/pluggy/_callers.py", line 133, in _multicall
    teardown[0].send(outcome)
  File "/usr/local/py-utils/venvs/pytest/lib/python3.10/site-packages/_pytest/helpconfig.py", line 103, in pytest_cmdline_parse
    config: Config = outcome.get_result()
  File "/usr/local/py-utils/venvs/pytest/lib/python3.10/site-packages/pluggy/_result.py", line 108, in get_result
    raise exc.with_traceback(exc.__traceback__)
  File "/usr/local/py-utils/venvs/pytest/lib/python3.10/site-packages/pluggy/_callers.py", line 80, in _multicall
    res = hook_impl.function(*args)
  File "/usr/local/py-utils/venvs/pytest/lib/python3.10/site-packages/_pytest/config/__init__.py", line 1075, in pytest_cmdline_parse
    self.parse(args)
  File "/usr/local/py-utils/venvs/pytest/lib/python3.10/site-packages/_pytest/config/__init__.py", line 1425, in parse
    self._preparse(args, addopts=addopts)
  File "/usr/local/py-utils/venvs/pytest/lib/python3.10/site-packages/_pytest/config/__init__.py", line 1305, in _preparse
    self.pluginmanager.load_setuptools_entrypoints("pytest11")
  File "/usr/local/py-utils/venvs/pytest/lib/python3.10/site-packages/pluggy/_manager.py", line 364, in load_setuptools_entrypoints
    plugin = ep.load()
  File "/usr/local/lib/python3.10/importlib/metadata/__init__.py", line 171, in load
    module = import_module(match.group('module'))
  File "/usr/local/lib/python3.10/importlib/__init__.py", line 126, in import_module
    return _bootstrap._gcd_import(name[level:], package, level)
  File "<frozen importlib._bootstrap>", line 1050, in _gcd_import
  File "<frozen importlib._bootstrap>", line 1027, in _find_and_load
  File "<frozen importlib._bootstrap>", line 1006, in _find_and_load_unlocked
  File "<frozen importlib._bootstrap>", line 688, in _load_unlocked
  File "/usr/local/py-utils/venvs/pytest/lib/python3.10/site-packages/_pytest/assertion/rewrite.py", line 178, in exec_module
    exec(co, module.__dict__)
  File "/usr/local/lib/python3.10/site-packages/pytest_icdiff.py", line 6, in <module>
    COLS = py.io.TerminalWriter().fullwidth  # pylint: disable=no-member
AttributeError: module 'py' has no attribute 'io'
